<mujoco model="gen3">
  <worldbody>
    <light name="spotlight" mode="targetbodycom" target="base_link" diffuse=".8 .8 .8" specular="0.3 0.3 0.3" pos="0 -6 4" cutoff="30"/>
    <body name="base_link" pos="0 0 0" quat="1 0 0 0">
      <joint name="joint_1" axis="1 0 0"/>
      <joint name="joint_2" axis="0 1 0"/>
      <joint name="joint_3" axis="0 0 1"/>
      <body name="link" pos="0 0 0" quat="1 0 0 0">
        <geom type="capsule" size="0.06" fromto="0 0 0  0 0 -.4"/>
      </body>
    </body>
  </worldbody>

  <actuator>
    <motor name="joint_1_motor" joint="joint_1" />
    <motor name="joint_2_motor" joint="joint_2" />
    <motor name="joint_3_motor" joint="joint_3" />
  </actuator>
</mujoco>
